<?xml version="1.0"?>
<robot xmlns:xacro="http://www.ros.org/wiki/xacro" name="tuppy">

    <xacro:macro name="box_inertia" params="m w h d">
        <inertial>
            <origin xyz="0 0 0" rpy="${pi/2} 0 ${pi/2}" />
            <mass value="${m}" />
            <inertia ixx="${(m/12) * (h*h + d*d)}" ixy="0.0" ixz="0.0" iyy="${(m/12) * (w*w + d*d)}"
                iyz="0.0" izz="${(m/12) * (w*w + h*h)}" />
        </inertial>
    </xacro:macro>

    <xacro:macro name="cylinder_inertia" params="m r h">
        <inertial>
            <origin xyz="0 0 0" rpy="${pi/2} 0 0" />
            <mass value="${m}" />
            <inertia ixx="${(m/12) * (3*r*r + h*h)}" ixy="0" ixz="0" iyy="${(m/12) * (3*r*r + h*h)}"
                iyz="0" izz="${(m/2) * (r*r)}" />
        </inertial>
    </xacro:macro>

    <link name="base_link">
        <visual>
            <origin xyz="0 0 0" />
            <geometry>
                <box size="0.4 0.25 0.1" />
            </geometry>
            <material name="white">
                <color rgba="1.0 1.0 1.0 1.0" />
            </material>
        </visual>
        <collision>
            <origin xyz="0 0 0" />
            <geometry>
                <box size="0.4 0.25 0.1" />
            </geometry>
        </collision>
        <xacro:box_inertia m="15" w="0.1" d="0.1" h="0.1" />
    </link>

    <link name="front_cross_beam">
        <visual>
            <origin xyz="0 0 0" />
            <geometry>
                <box size="0.025 0.5 0.025" />
            </geometry>
            <material name="white">
                <color rgba="1.0 1.0 1.0 1.0" />
            </material>
        </visual>
        <collision>
            <origin xyz="0 0 0" />
            <geometry>
                <box size="0.025 0.5 0.025" />
            </geometry>
        </collision>
        <xacro:box_inertia m="15" w="0.1" d="0.1" h="0.1" />
    </link>

    <link name="center_cross_beam">
        <visual>
            <origin xyz="0 0 0" />
            <geometry>
                <box size="0.025 0.5 0.025" />
            </geometry>
            <material name="white">
                <color rgba="1.0 1.0 1.0 1.0" />
            </material>
        </visual>
        <collision>
            <origin xyz="0 0 0" />
            <geometry>
                <box size="0.025 0.5 0.025" />
            </geometry>
        </collision>
        <xacro:box_inertia m="15" w="0.1" d="0.1" h="0.1" />
    </link>

    <link name="rear_cross_beam">
        <visual>
            <origin xyz="0 0 0" />
            <geometry>
                <box size="0.025 0.5 0.025" />
            </geometry>
            <material name="white">
                <color rgba="1.0 1.0 1.0 1.0" />
            </material>
        </visual>
        <collision>
            <origin xyz="0 0 0" />
            <geometry>
                <box size="0.025 0.5 0.025" />
            </geometry>
        </collision>
        <xacro:box_inertia m="15" w="0.1" d="0.1" h="0.1" />
    </link>

    <link name="left_float">
        <visual>
            <origin xyz="0 0 0" />
            <geometry>
                <box size="0.8 0.15 0.15" />
            </geometry>
            <material name="white">
                <color rgba="1.0 1.0 1.0 1.0" />
            </material>
        </visual>
        <collision>
            <origin xyz="0 0 0" />
            <geometry>
                <box size="0.8 0.15 0.15" />
            </geometry>
        </collision>
        <xacro:box_inertia m="15" w="0.1" d="0.1" h="0.1" />
    </link>

    <link name="right_float">
        <visual>
            <origin xyz="0 0 0" />
            <geometry>
                <box size="0.8 0.15 0.15" />
            </geometry>
            <material name="white">
                <color rgba="1.0 1.0 1.0 1.0" />
            </material>
        </visual>
        <collision>
            <origin xyz="0 0 0" />
            <geometry>
                <box size="0.8 0.15 0.15" />
            </geometry>
        </collision>
        <xacro:box_inertia m="15" w="0.1" d="0.1" h="0.1" />
    </link>

    <link name="lidar_link">
        <visual>
            <origin xyz="0 0 0" />
            <geometry>
                <cylinder radius="0.05" length="0.07" />
            </geometry>
            <material name="white">
                <color rgba="1.0 1.0 1.0 1.0" />
            </material>
        </visual>
        <collision>
            <origin xyz="0 0 0" />
            <geometry>
                <cylinder radius="0.05" length="0.07" />
            </geometry>
        </collision>
        <xacro:cylinder_inertia m="0.5" r="0.05" h="0.07" />
    </link>

    <link name="left_propeller">
        <visual>
            <origin xyz="0 0 0" />
            <geometry>
                <cylinder radius="0.05" length="0.025" />
            </geometry>
            <material name="red">
                <color rgba="1.0 0.0 0.0 1.0" />
            </material>
        </visual>
        <!-- <collision>
            <origin xyz="0 0 0" />
            <geometry>
                <cylinder radius="0.05" length="0.025" />
            </geometry>
        </collision> -->
        <xacro:cylinder_inertia m="0.5" r="0.05" h="0.07" />
    </link>

    <link name="right_propeller">
        <visual>
            <origin xyz="0 0 0" />
            <geometry>
                <cylinder radius="0.05" length="0.025" />
            </geometry>
            <material name="red">
                <color rgba="1.0 0.0 0.0 1.0" />
            </material>
        </visual>
        <!-- <collision>
            <origin xyz="0 0 0" />
            <geometry>
                <cylinder radius="0.05" length="0.025" />
            </geometry>
        </collision> -->
        <xacro:cylinder_inertia m="0.5" r="0.05" h="0.07" />
    </link>

    <joint name="front_cross_bream_joint" type="fixed">
        <parent link="base_link" />
        <child link="front_cross_beam" />
        <origin xyz="0.35 0.0 -0.0625" />
    </joint>

    <joint name="center_cross_bream_joint" type="fixed">
        <parent link="base_link" />
        <child link="center_cross_beam" />
        <origin xyz="0.15 0.0 -0.0625" />
    </joint>

    <joint name="rear_cross_bream_joint" type="fixed">
        <parent link="base_link" />
        <child link="rear_cross_beam" />
        <origin xyz="-0.15 0.0 -0.0625" />
    </joint>

    <joint name="left_float_joint" type="fixed">
        <parent link="base_link" />
        <child link="left_float" />
        <origin xyz="0.15 0.25 -0.15" />
    </joint>

    <joint name="right_float_joint" type="fixed">
        <parent link="base_link" />
        <child link="right_float" />
        <origin xyz="0.15 -0.25 -0.15" />
    </joint>

    <joint name="lidar_joint" type="fixed">
        <parent link="base_link" />
        <child link="lidar_link" />
        <origin xyz="0.35 0.0 -0.015" />
    </joint>

    <joint name="left_prop_joint" type="continuous">
        <parent link="base_link" />
        <child link="left_propeller" />
        <axis xyz="0 0 1" />
        <origin xyz="-0.3 0.25 -0.25" rpy="0 ${pi/2} 0" />
    </joint>

    <joint name="right_prop_joint" type="continuous">
        <parent link="base_link" />
        <child link="right_propeller" />
        <axis xyz="0 0 1" />
        <origin xyz="-0.3 -0.25 -0.25" rpy="0 ${pi/2} 0" />
    </joint>

    <!-- IMU -->

    <link name="imu_link">
        <visual>
            <geometry>
                <box size="0.025 0.025 0.025" />
            </geometry>
            <material name="green">
                <color rgba="0.0 1.0 0.0 1.0" />
            </material>
        </visual>
        <collision>
            <geometry>
                <box size="0.025 0.025 0.025" />
            </geometry>
        </collision>
        <xacro:box_inertia m="0.1" w="0.1" d="0.1" h="0.1" />
    </link>

    <joint name="imu_joint" type="fixed">
        <parent link="base_link" />
        <child link="imu_link" />
        <origin xyz="0.15 0 0" />
    </joint>

    <gazebo reference="imu_link">
        <sensor name="imu_sensor" type="imu">
            <plugin filename="libgazebo_ros_imu_sensor.so" name="imu_plugin">
                <ros>
                    <namespace>/demo</namespace>
                    <remapping>~/out:=imu</remapping>
                </ros>
                <initial_orientation_as_reference>false</initial_orientation_as_reference>
            </plugin>
            <always_on>true</always_on>
            <update_rate>100</update_rate>
            <visualize>true</visualize>
            <imu>
                <angular_velocity>
                    <x>
                        <noise type="gaussian">
                            <mean>0.0</mean>
                            <stddev>2e-4</stddev>
                            <bias_mean>0.0000075</bias_mean>
                            <bias_stddev>0.0000008</bias_stddev>
                        </noise>
                    </x>
                    <y>
                        <noise type="gaussian">
                            <mean>0.0</mean>
                            <stddev>2e-4</stddev>
                            <bias_mean>0.0000075</bias_mean>
                            <bias_stddev>0.0000008</bias_stddev>
                        </noise>
                    </y>
                    <z>
                        <noise type="gaussian">
                            <mean>0.0</mean>
                            <stddev>2e-4</stddev>
                            <bias_mean>0.0000075</bias_mean>
                            <bias_stddev>0.0000008</bias_stddev>
                        </noise>
                    </z>
                </angular_velocity>
                <linear_acceleration>
                    <x>
                        <noise type="gaussian">
                            <mean>0.0</mean>
                            <stddev>1.7e-2</stddev>
                            <bias_mean>0.1</bias_mean>
                            <bias_stddev>0.001</bias_stddev>
                        </noise>
                    </x>
                    <y>
                        <noise type="gaussian">
                            <mean>0.0</mean>
                            <stddev>1.7e-2</stddev>
                            <bias_mean>0.1</bias_mean>
                            <bias_stddev>0.001</bias_stddev>
                        </noise>
                    </y>
                    <z>
                        <noise type="gaussian">
                            <mean>0.0</mean>
                            <stddev>1.7e-2</stddev>
                            <bias_mean>0.1</bias_mean>
                            <bias_stddev>0.001</bias_stddev>
                        </noise>
                    </z>
                </linear_acceleration>
            </imu>
        </sensor>
    </gazebo>

    <!-- LIDAR -->

    <gazebo reference="lidar_link">
        <sensor name="lidar" type="ray">
            <always_on>true</always_on>
            <visualize>true</visualize>
            <update_rate>5</update_rate>
            <ray>
                <scan>
                    <horizontal>
                        <samples>360</samples>
                        <resolution>1.000000</resolution>
                        <min_angle>0.000000</min_angle>
                        <max_angle>6.280000</max_angle>
                    </horizontal>
                </scan>
                <range>
                    <min>0.120000</min>
                    <max>3.5</max>
                    <resolution>0.015000</resolution>
                </range>
                <noise>
                    <type>gaussian</type>
                    <mean>0.0</mean>
                    <stddev>0.01</stddev>
                </noise>
            </ray>
            <plugin name="scan" filename="libgazebo_ros_ray_sensor.so">
                <ros>
                    <remapping>~/out:=scan</remapping>
                </ros>
                <output_type>sensor_msgs/LaserScan</output_type>
                <frame_name>lidar_link</frame_name>
            </plugin>
        </sensor>
    </gazebo>

</robot>